Workbook

Sheet Sheet1
A1: TCs Name | B1: Platform | C1: Priority | D1: Release | E1: Result | F1: Automated
A2: Product Summary - Savings Accounts List | B2: WEB | C2: {=_xlfn.LET(_xlpm.name1,LOWER(TRIM(SUBSTITUTE(A2,"_"," "))),_xlpm.platform1,LOWER(TRIM(B2)),_xlpm.name2,LOWER(TRIM(SUBSTITUTE(_xlfn.TEXTBEFORE(Sheet2!$A$2:$A$1000,"["),"_"," "))),_xlpm.platform2,LOWER(TRIM(Sheet2!$B$2:$B$1000)),_xlfn.XLOOKUP(_xlpm.name1&"|"&_xlpm.platform1,_xlpm.name2&"|"&_xlpm.platform2,Sheet2!$C$2:$C$1000,""))} -> High | D2: Release12_1 | E2: PASSED | F2: Automated
A3: Product Summary - Savings Accounts List | B3: iOS | C3: {=_xlfn.LET(_xlpm.name1,LOWER(TRIM(SUBSTITUTE(A3,"_"," "))),_xlpm.platform1,LOWER(TRIM(B3)),_xlpm.name2,LOWER(TRIM(SUBSTITUTE(_xlfn.TEXTBEFORE(Sheet2!$A$2:$A$1000,"["),"_"," "))),_xlpm.platform2,LOWER(TRIM(Sheet2!$B$2:$B$1000)),_xlfn.XLOOKUP(_xlpm.name1&"|"&_xlpm.platform1,_xlpm.name2&"|"&_xlpm.platform2,Sheet2!$C$2:$C$1000,""))} -> High | D3: Release12_1 | E3: PASSED | F3: Automated
A4: Product Summary - Savings Accounts List | B4: Android | C4: {=_xlfn.LET(_xlpm.name1,LOWER(TRIM(SUBSTITUTE(A4,"_"," "))),_xlpm.platform1,LOWER(TRIM(B4)),_xlpm.name2,LOWER(TRIM(SUBSTITUTE(_xlfn.TEXTBEFORE(Sheet2!$A$2:$A$1000,"["),"_"," "))),_xlpm.platform2,LOWER(TRIM(Sheet2!$B$2:$B$1000)),_xlfn.XLOOKUP(_xlpm.name1&"|"&_xlpm.platform1,_xlpm.name2&"|"&_xlpm.platform2,Sheet2!$C$2:$C$1000,""))} -> High | D4: Release12_1 | E4: PASSED | F4: Automated
A5: Term Deposits Accounts - Details | B5: WEB | C5: {=_xlfn.LET(_xlpm.name1,LOWER(TRIM(SUBSTITUTE(A5,"_"," "))),_xlpm.platform1,LOWER(TRIM(B5)),_xlpm.name2,LOWER(TRIM(SUBSTITUTE(_xlfn.TEXTBEFORE(Sheet2!$A$2:$A$1000,"["),"_"," "))),_xlpm.platform2,LOWER(TRIM(Sheet2!$B$2:$B$1000)),_xlfn.XLOOKUP(_xlpm.name1&"|"&_xlpm.platform1,_xlpm.name2&"|"&_xlpm.platform2,Sheet2!$C$2:$C$1000,""))} -> High | D5: Release12_1 | E5: PASSED | F5: Automated
A6: Term Deposits Accounts - Details - Financial Details | B6: WEB | C6: {=_xlfn.LET(_xlpm.name1,LOWER(TRIM(SUBSTITUTE(A6,"_"," "))),_xlpm.platform1,LOWER(TRIM(B6)),_xlpm.name2,LOWER(TRIM(SUBSTITUTE(_xlfn.TEXTBEFORE(Sheet2!$A$2:$A$1000,"["),"_"," "))),_xlpm.platform2,LOWER(TRIM(Sheet2!$B$2:$B$1000)),_xlfn.XLOOKUP(_xlpm.name1&"|"&_xlpm.platform1,_xlpm.name2&"|"&_xlpm.platform2,Sheet2!$C$2:$C$1000,""))} -> Critical | D6: Release12_1 | E6: PASSED | F6: Automated
A7: Term Deposits Accounts - Details - Account Details | B7: WEB | C7: {=_xlfn.LET(_xlpm.name1,LOWER(TRIM(SUBSTITUTE(A7,"_"," "))),_xlpm.platform1,LOWER(TRIM(B7)),_xlpm.name2,LOWER(TRIM(SUBSTITUTE(_xlfn.TEXTBEFORE(Sheet2!$A$2:$A$1000,"["),"_"," "))),_xlpm.platform2,LOWER(TRIM(Sheet2!$B$2:$B$1000)),_xlfn.XLOOKUP(_xlpm.name1&"|"&_xlpm.platform1,_xlpm.name2&"|"&_xlpm.platform2,Sheet2!$C$2:$C$1000,""))} -> Critical | D7: Release12_1 | E7: PASSED | F7: Automated
A8: Term Deposits Accounts - Details | B8: iOS | C8: {=_xlfn.LET(_xlpm.name1,LOWER(TRIM(SUBSTITUTE(A8,"_"," "))),_xlpm.platform1,LOWER(TRIM(B8)),_xlpm.name2,LOWER(TRIM(SUBSTITUTE(_xlfn.TEXTBEFORE(Sheet2!$A$2:$A$1000,"["),"_"," "))),_xlpm.platform2,LOWER(TRIM(Sheet2!$B$2:$B$1000)),_xlfn.XLOOKUP(_xlpm.name1&"|"&_xlpm.platform1,_xlpm.name2&"|"&_xlpm.platform2,Sheet2!$C$2:$C$1000,""))} -> High | D8: Release12_1 | E8: FAILED | F8: Not Automated
A9: Term Deposits Accounts - Details - Financial Details | B9: iOS | C9: {=_xlfn.LET(_xlpm.name1,LOWER(TRIM(SUBSTITUTE(A9,"_"," "))),_xlpm.platform1,LOWER(TRIM(B9)),_xlpm.name2,LOWER(TRIM(SUBSTITUTE(_xlfn.TEXTBEFORE(Sheet2!$A$2:$A$1000,"["),"_"," "))),_xlpm.platform2,LOWER(TRIM(Sheet2!$B$2:$B$1000)),_xlfn.XLOOKUP(_xlpm.name1&"|"&_xlpm.platform1,_xlpm.name2&"|"&_xlpm.platform2,Sheet2!$C$2:$C$1000,""))} -> Critical | D9: Release12_1 | E9: FAILED | F9: Not Automated
A10: Term Deposits Accounts - Details - Account Details | B10: iOS | C10: {=_xlfn.LET(_xlpm.name1,LOWER(TRIM(SUBSTITUTE(A10,"_"," "))),_xlpm.platform1,LOWER(TRIM(B10)),_xlpm.name2,LOWER(TRIM(SUBSTITUTE(_xlfn.TEXTBEFORE(Sheet2!$A$2:$A$1000,"["),"_"," "))),_xlpm.platform2,LOWER(TRIM(Sheet2!$B$2:$B$1000)),_xlfn.XLOOKUP(_xlpm.name1&"|"&_xlpm.platform1,_xlpm.name2&"|"&_xlpm.platform2,Sheet2!$C$2:$C$1000,""))} -> Critical | D10: Release12_1 | E10: PASSED | F10: Automated
A11: Term Deposits Accounts - Details | B11: Android | C11: {=_xlfn.LET(_xlpm.name1,LOWER(TRIM(SUBSTITUTE(A11,"_"," "))),_xlpm.platform1,LOWER(TRIM(B11)),_xlpm.name2,LOWER(TRIM(SUBSTITUTE(_xlfn.TEXTBEFORE(Sheet2!$A$2:$A$1000,"["),"_"," "))),_xlpm.platform2,LOWER(TRIM(Sheet2!$B$2:$B$1000)),_xlfn.XLOOKUP(_xlpm.name1&"|"&_xlpm.platform1,_xlpm.name2&"|"&_xlpm.platform2,Sheet2!$C$2:$C$1000,""))} -> High | D11: Release12_1 | E11: PASSED | F11: Automated
A12: Term Deposits Accounts - Details - Financial Details | B12: Android | C12: {=_xlfn.LET(_xlpm.name1,LOWER(TRIM(SUBSTITUTE(A12,"_"," "))),_xlpm.platform1,LOWER(TRIM(B12)),_xlpm.name2,LOWER(TRIM(SUBSTITUTE(_xlfn.TEXTBEFORE(Sheet2!$A$2:$A$1000,"["),"_"," "))),_xlpm.platform2,LOWER(TRIM(Sheet2!$B$2:$B$1000)),_xlfn.XLOOKUP(_xlpm.name1&"|"&_xlpm.platform1,_xlpm.name2&"|"&_xlpm.platform2,Sheet2!$C$2:$C$1000,""))} -> Critical | D12: Release12_1 | E12: FAILED | F12: Not Automated
A13: Term Deposits Accounts - Details - Account Details | B13: Android | C13: {=_xlfn.LET(_xlpm.name1,LOWER(TRIM(SUBSTITUTE(A13,"_"," "))),_xlpm.platform1,LOWER(TRIM(B13)),_xlpm.name2,LOWER(TRIM(SUBSTITUTE(_xlfn.TEXTBEFORE(Sheet2!$A$2:$A$1000,"["),"_"," "))),_xlpm.platform2,LOWER(TRIM(Sheet2!$B$2:$B$1000)),_xlfn.XLOOKUP(_xlpm.name1&"|"&_xlpm.platform1,_xlpm.name2&"|"&_xlpm.platform2,Sheet2!$C$2:$C$1000,""))} -> Critical | D13: Release12_1 | E13: PASSED | F13: Automated
... A829: PAYMENTS_RECIPIENT_TEMPLATE DETAILS_[MOB_ANDROID | B829: Android | C829: {=_xlfn.LET(_xlpm.name1,LOWER(TRIM(SUBSTITUTE(A829,"_"," "))),_xlpm.platform1,LOWER(TRIM(B829)),_xlpm.name2,LOWER(TRIM(SUBSTITUTE(_xlfn.TEXTBEFORE(Sheet2!$A$2:$A$1000,"["),"_"," "))),_xlpm.platform2,LOWER(TRIM(Sheet2!$B$2:$B$1000)),_xlfn.XLOOKUP(_xlpm.name1&"|"&_xlpm.platform1,_xlpm.name2&"|"&_xlpm.platform2,Sheet2!$C$2:$C$1000,""))} | D829: Release 4 | E829: PASSED | F829: Not Automated
A830: PAYMENTS_RECIPIENT_SAVE TEMPLATES DURING PAYMENT PROCESS [Android] | C830: {=_xlfn.LET(_xlpm.name1,LOWER(TRIM(SUBSTITUTE(A830,"_"," "))),_xlpm.platform1,LOWER(TRIM(B830)),_xlpm.name2,LOWER(TRIM(SUBSTITUTE(_xlfn.TEXTBEFORE(Sheet2!$A$2:$A$1000,"["),"_"," "))),_xlpm.platform2,LOWER(TRIM(Sheet2!$B$2:$B$1000)),_xlfn.XLOOKUP(_xlpm.name1&"|"&_xlpm.platform1,_xlpm.name2&"|"&_xlpm.platform2,Sheet2!$C$2:$C$1000,""))} | D830: Release 4 | E830: PASSED | F830: Not Automated
A831: PAYMENTS_RECIPIENT_DELETE TEMPLATE_[WEB] | B831: WEB | C831: {=_xlfn.LET(_xlpm.name1,LOWER(TRIM(SUBSTITUTE(A831,"_"," "))),_xlpm.platform1,LOWER(TRIM(B831)),_xlpm.name2,LOWER(TRIM(SUBSTITUTE(_xlfn.TEXTBEFORE(Sheet2!$A$2:$A$1000,"["),"_"," "))),_xlpm.platform2,LOWER(TRIM(Sheet2!$B$2:$B$1000)),_xlfn.XLOOKUP(_xlpm.name1&"|"&_xlpm.platform1,_xlpm.name2&"|"&_xlpm.platform2,Sheet2!$C$2:$C$1000,""))} | D831: Release 4 | E831: PASSED | F831: Not Automated
A832: PAYMENTS_RECIPIENT_EDIT TEMPLATE_[WEB] | B832: WEB | C832: {=_xlfn.LET(_xlpm.name1,LOWER(TRIM(SUBSTITUTE(A832,"_"," "))),_xlpm.platform1,LOWER(TRIM(B832)),_xlpm.name2,LOWER(TRIM(SUBSTITUTE(_xlfn.TEXTBEFORE(Sheet2!$A$2:$A$1000,"["),"_"," "))),_xlpm.platform2,LOWER(TRIM(Sheet2!$B$2:$B$1000)),_xlfn.XLOOKUP(_xlpm.name1&"|"&_xlpm.platform1,_xlpm.name2&"|"&_xlpm.platform2,Sheet2!$C$2:$C$1000,""))} | D832: Release 4 | E832: PASSED | F832: Not Automated
A833: PAYMENTS_RECIPIENT_EDIT TEMPLATE - invalid_[WEB] | B833: WEB | C833: {=_xlfn.LET(_xlpm.name1,LOWER(TRIM(SUBSTITUTE(A833,"_"," "))),_xlpm.platform1,LOWER(TRIM(B833)),_xlpm.name2,LOWER(TRIM(SUBSTITUTE(_xlfn.TEXTBEFORE(Sheet2!$A$2:$A$1000,"["),"_"," "))),_xlpm.platform2,LOWER(TRIM(Sheet2!$B$2:$B$1000)),_xlfn.XLOOKUP(_xlpm.name1&"|"&_xlpm.platform1,_xlpm.name2&"|"&_xlpm.platform2,Sheet2!$C$2:$C$1000,""))} | D833: Release 4 | E833: PASSED | F833: Not Automated
A834: PAYMENTS_RECIPIENT_DELETE TEMPLATE_[MOB_ANDROID] | B834: Android | C834: {=_xlfn.LET(_xlpm.name1,LOWER(TRIM(SUBSTITUTE(A834,"_"," "))),_xlpm.platform1,LOWER(TRIM(B834)),_xlpm.name2,LOWER(TRIM(SUBSTITUTE(_xlfn.TEXTBEFORE(Sheet2!$A$2:$A$1000,"["),"_"," "))),_xlpm.platform2,LOWER(TRIM(Sheet2!$B$2:$B$1000)),_xlfn.XLOOKUP(_xlpm.name1&"|"&_xlpm.platform1,_xlpm.name2&"|"&_xlpm.platform2,Sheet2!$C$2:$C$1000,""))} | D834: Release 4 | E834: PASSED | F834: Not Automated
A835: PAYMENTS_RECIPIENT_EDIT TEMPLATE_[MOB_ANDROID] | B835: Android | C835: {=_xlfn.LET(_xlpm.name1,LOWER(TRIM(SUBSTITUTE(A835,"_"," "))),_xlpm.platform1,LOWER(TRIM(B835)),_xlpm.name2,LOWER(TRIM(SUBSTITUTE(_xlfn.TEXTBEFORE(Sheet2!$A$2:$A$1000,"["),"_"," "))),_xlpm.platform2,LOWER(TRIM(Sheet2!$B$2:$B$1000)),_xlfn.XLOOKUP(_xlpm.name1&"|"&_xlpm.platform1,_xlpm.name2&"|"&_xlpm.platform2,Sheet2!$C$2:$C$1000,""))} | D835: Release 4 | E835: PASSED | F835: Not Automated
A836: PAYMENTS_RECIPIENT_EDIT TEMPLATE - invalid_[MOB_ANDROID] | B836: Android | C836: {=_xlfn.LET(_xlpm.name1,LOWER(TRIM(SUBSTITUTE(A836,"_"," "))),_xlpm.platform1,LOWER(TRIM(B836)),_xlpm.name2,LOWER(TRIM(SUBSTITUTE(_xlfn.TEXTBEFORE(Sheet2!$A$2:$A$1000,"["),"_"," "))),_xlpm.platform2,LOWER(TRIM(Sheet2!$B$2:$B$1000)),_xlfn.XLOOKUP(_xlpm.name1&"|"&_xlpm.platform1,_xlpm.name2&"|"&_xlpm.platform2,Sheet2!$C$2:$C$1000,""))} | D836: Release 4 | E836: PASSED | F836: Not Automated
A837: PAYMENTS_RECIPIENT_DELETE TEMPLATE_[MOB_IOS] | B837: iOS | C837: {=_xlfn.LET(_xlpm.name1,LOWER(TRIM(SUBSTITUTE(A837,"_"," "))),_xlpm.platform1,LOWER(TRIM(B837)),_xlpm.name2,LOWER(TRIM(SUBSTITUTE(_xlfn.TEXTBEFORE(Sheet2!$A$2:$A$1000,"["),"_"," "))),_xlpm.platform2,LOWER(TRIM(Sheet2!$B$2:$B$1000)),_xlfn.XLOOKUP(_xlpm.name1&"|"&_xlpm.platform1,_xlpm.name2&"|"&_xlpm.platform2,Sheet2!$C$2:$C$1000,""))} | D837: Release 4 | E837: PASSED | F837: Not Automated
A838: PAYMENTS_RECIPIENT_EDIT TEMPLATE_[MOB_IOS] | B838: iOS | C838: {=_xlfn.LET(_xlpm.name1,LOWER(TRIM(SUBSTITUTE(A838,"_"," "))),_xlpm.platform1,LOWER(TRIM(B838)),_xlpm.name2,LOWER(TRIM(SUBSTITUTE(_xlfn.TEXTBEFORE(Sheet2!$A$2:$A$1000,"["),"_"," "))),_xlpm.platform2,LOWER(TRIM(Sheet2!$B$2:$B$1000)),_xlfn.XLOOKUP(_xlpm.name1&"|"&_xlpm.platform1,_xlpm.name2&"|"&_xlpm.platform2,Sheet2!$C$2:$C$1000,""))} | D838: Release 4 | E838: PASSED | F838: Not Automated
A839: PAYMENTS_RECIPIENT_EDIT TEMPLATE - invalid_[MOB_IOS] | B839: iOS | C839: {=_xlfn.LET(_xlpm.name1,LOWER(TRIM(SUBSTITUTE(A839,"_"," "))),_xlpm.platform1,LOWER(TRIM(B839)),_xlpm.name2,LOWER(TRIM(SUBSTITUTE(_xlfn.TEXTBEFORE(Sheet2!$A$2:$A$1000,"["),"_"," "))),_xlpm.platform2,LOWER(TRIM(Sheet2!$B$2:$B$1000)),_xlfn.XLOOKUP(_xlpm.name1&"|"&_xlpm.platform1,_xlpm.name2&"|"&_xlpm.platform2,Sheet2!$C$2:$C$1000,""))} | D839: Release 4 | E839: PASSED | F839: Not Automated

Sheet Sheet2
A1: Title | B1: Platform | C1: Priority | D1: Release | E1: Status
A2: Product_Summary_Sorting on the Product Summary_[WEB] | B2: =_xlfn.TEXTBEFORE(_xlfn.TEXTAFTER(A2,"["),"]") -> WEB | C2: Sanity | D2: Release 1 | E2: Failed - Old bug
A3: Product_Summary_Sorting on the Product Summary_[ANDROID] | B3: =_xlfn.TEXTBEFORE(_xlfn.TEXTAFTER(A3,"["),"]") -> ANDROID | C3: Sanity | D3: Release 1 | E3: Failed - Old bug
A4: Product_Summary_Sorting on the Product Summary_[iOS] | B4: =_xlfn.TEXTBEFORE(_xlfn.TEXTAFTER(A4,"["),"]") -> iOS | C4: Sanity | D4: Release 1 | E4: Failed - Old bug
A5: CURRENT DOMESTIC ACCOUNTS - DETAILS - FINANCIAL DETAILS_[WEB] | B5: =_xlfn.TEXTBEFORE(_xlfn.TEXTAFTER(A5,"["),"]") -> WEB | C5: Sanity | D5: Release 1 | E5: Failed - New bug
A6: CURRENT DOMESTIC ACCOUNTS - DETAILS - ACCOUNT DETAILS_[WEB] | B6: =_xlfn.TEXTBEFORE(_xlfn.TEXTAFTER(A6,"["),"]") -> WEB | C6: Sanity | D6: Release 1 | E6: Failed - New bug
A7: CURRENT DOMESTIC ACCOUNTS - DETAILS - FINANCIAL DETAILS_[Android] | B7: =_xlfn.TEXTBEFORE(_xlfn.TEXTAFTER(A7,"["),"]") -> Android | C7: Sanity | D7: Release 1 | E7: Failed - Old bug
A8: CURRENT DOMESTIC ACCOUNTS - DETAILS - ACCOUNT DETAILS_[Android] | B8: =_xlfn.TEXTBEFORE(_xlfn.TEXTAFTER(A8,"["),"]") -> Android | C8: Sanity | D8: Release 1 | E8: Blocked by bug
A9: CURRENT DOMESTIC ACCOUNTS - DETAILS - FINANCIAL DETAILS_[iOS] | B9: =_xlfn.TEXTBEFORE(_xlfn.TEXTAFTER(A9,"["),"]") -> iOS | C9: Sanity | D9: Release 1 | E9: Passed
A10: CURRENT DOMESTIC ACCOUNTS - DETAILS - ACCOUNT DETAILS_[iOS] | B10: =_xlfn.TEXTBEFORE(_xlfn.TEXTAFTER(A10,"["),"]") -> iOS | C10: Sanity | D10: Release 1 | E10: Passed
A11: SAVINGS ACCOUNTS - DETAILS - FINANCIAL DETAILS_[WEB] | B11: =_xlfn.TEXTBEFORE(_xlfn.TEXTAFTER(A11,"["),"]") -> WEB | C11: Sanity | D11: Release 1 | E11: Passed
A12: SAVINGS ACCOUNTS - DETAILS - ACCOUNT DETAILS_[WEB] | B12: =_xlfn.TEXTBEFORE(_xlfn.TEXTAFTER(A12,"["),"]") -> WEB | C12: Sanity | D12: Release 1 | E12: Passed
A13: SAVINGS ACCOUNTS - DETAILS - FINANCIAL DETAILS_[Android] | B13: =_xlfn.TEXTBEFORE(_xlfn.TEXTAFTER(A13,"["),"]") -> Android | C13: Sanity | D13: Release 1 | E13: Passed
... A41: AUTHENTICATION- TOKEN ACTIVATION -Activate Token_GET NEW ACTIVATION CODES_ [iOS] | B41: =_xlfn.TEXTBEFORE(_xlfn.TEXTAFTER(A41,"["),"]") -> iOS | C41: Sanity | D41: Release 2 | E41: Conditionally Passed
A42: SELF SERVICE_ENABLE BIOMETRICS_[Android] | B42: =_xlfn.TEXTBEFORE(_xlfn.TEXTAFTER(A42,"["),"]") -> Android | C42: Sanity | E42: Passed
A43: SELF SERVICE_DISABLE BIOMETRICS_[Android] | B43: =_xlfn.TEXTBEFORE(_xlfn.TEXTAFTER(A43,"["),"]") -> Android | C43: Sanity | E43: Passed
A44: SELF SERVICE_ENABLE BIOMETRICS_[iOS] | B44: =_xlfn.TEXTBEFORE(_xlfn.TEXTAFTER(A44,"["),"]") -> iOS | C44: Sanity | E44: Passed
A45: SELF SERVICE_DISABLE BIOMETRICS_[iOS] | B45: =_xlfn.TEXTBEFORE(_xlfn.TEXTAFTER(A45,"["),"]") -> iOS | C45: Sanity | E45: Passed
A46: PAYMENTS - OWN ACCOUNT TRANSFER_FROM CURRENT ACCOUNT RSD[WEB] | B46: =_xlfn.TEXTBEFORE(_xlfn.TEXTAFTER(A46,"["),"]") -> WEB | C46: Sanity | D46: Release 2 | E46: Failed - New bug
A47: PAYMENTS - OWN ACCOUNT TRANSFER_FROM CURRENT ACCOUNT RSD TO CURRENT ACCOUNT RSD [WEB] | B47: =_xlfn.TEXTBEFORE(_xlfn.TEXTAFTER(A47,"["),"]") -> WEB | C47: Sanity | D47: Release 2 | E47: Conditionally Passed
A48: PAYMENTS - OWN ACCOUNT TRANSFER_FROM CURRENT ACCOUNT RSD [ANDROID] | B48: =_xlfn.TEXTBEFORE(_xlfn.TEXTAFTER(A48,"["),"]") -> ANDROID | C48: Sanity | D48: Release 2 | E48: Failed - New bug
A49: PAYMENTS - OWN ACCOUNT TRANSFER_FROM CURRENT ACCOUNT RSD TO CURRENT ACCOUNT RSD [ANDROID] | B49: =_xlfn.TEXTBEFORE(_xlfn.TEXTAFTER(A49,"["),"]") -> ANDROID | C49: Sanity | D49: Release 2 | E49: Failed - New bug
A50: PAYMENTS - OWN ACCOUNT TRANSFER_FROM CURRENT ACCOUNT RSD [IOS] | B50: =_xlfn.TEXTBEFORE(_xlfn.TEXTAFTER(A50,"["),"]") -> IOS | C50: Sanity | D50: Release 2 | E50: Failed - New bug
A51: PAYMENTS - OWN ACCOUNT TRANSFER_FROM CURRENT ACCOUNT RSD TO CURRENT ACCOUNT RSD [IOS] | B51: =_xlfn.TEXTBEFORE(_xlfn.TEXTAFTER(A51,"["),"]") -> IOS | C51: Sanity | D51: Release 2 | E51: Passed
A52: PAYMENTS - DOMESTIC PAYMENTS_[WEB] | B52: =_xlfn.TEXTBEFORE(_xlfn.TEXTAFTER(A52,"["),"]") -> WEB | C52: Sanity | D52: Release 2 | E52: Conditionally Passed
A53: PAYMENTS - DOMESTIC PAYMENTS_[Android] | B53: =_xlfn.TEXTBEFORE(_xlfn.TEXTAFTER(A53,"["),"]") -> Android | C53: Sanity | D53: Release 2 | E53: Passed
A54: PAYMENTS - DOMESTIC PAYMENTS_[iOS] | B54: =_xlfn.TEXTBEFORE(_xlfn.TEXTAFTER(A54,"["),"]") -> iOS | C54: Sanity | D54: Release 2 | E54: Passed
A55: PAYMENTS-SCAN AND PAY_SUCCESSFUL PAYMENT VIA THE SCAN AND PAY OPTION_[iOS] | B55: =_xlfn.TEXTBEFORE(_xlfn.TEXTAFTER(A55,"["),"]") -> iOS | C55: Sanity | D55: Release 2 | E55: Passed
A56: PAYMENTS_PAY FROM GALLERY_SUCCESSFUL PAYMENT VIA THE PAY FROM GALLERY OPTION_[iOS] | B56: =_xlfn.TEXTBEFORE(_xlfn.TEXTAFTER(A56,"["),"]") -> iOS | C56: Sanity | D56: Release 2 | E56: Passed
A57: PAYMENTS_SCAN AND PAY_SUCCESSFUL PAYMENT VIA THE SCAN AND PAY OPTION_[Android] | B57: =_xlfn.TEXTBEFORE(_xlfn.TEXTAFTER(A57,"["),"]") -> Android | C57: Sanity | D57: Release 2 | E57: Passed
... A64: CURRENT FOREIGN/SAVINGS ACCOUNTS - TRANSACTIONS - DETAILS_[iOS] | B64: =_xlfn.TEXTBEFORE(_xlfn.TEXTAFTER(A64,"["),"]") -> iOS | C64: Sanity | D64: Release 1 | E64: Blocked by bug
A65: CURRENT DOMESTIC ACCOUNTS - TRANSACTIONS - DETAILS_[WEB] | B65: =_xlfn.TEXTBEFORE(_xlfn.TEXTAFTER(A65,"["),"]") -> WEB | C65: Sanity | E65: Failed - New bug
A66: CURRENT DOMESTIC ACCOUNTS - TRANSACTIONS - DETAILS_[Android] | B66: =_xlfn.TEXTBEFORE(_xlfn.TEXTAFTER(A66,"["),"]") -> Android | C66: Sanity | E66: Blocked by bug
A67: CURRENT DOMESTIC ACCOUNTS - TRANSACTIONS - DETAILS_[iOS] | B67: =_xlfn.TEXTBEFORE(_xlfn.TEXTAFTER(A67,"["),"]") -> iOS | C67: Sanity | E67: Blocked by bug
A68: CARDS- TRANSACTIONS - DETAILS_[iOS] | B68: =_xlfn.TEXTBEFORE(_xlfn.TEXTAFTER(A68,"["),"]") -> iOS | C68: Sanity | D68: Release 2 | E68: Passed
A69: CARDS- TRANSACTIONS - DETAILS_[WEB] | B69: =_xlfn.TEXTBEFORE(_xlfn.TEXTAFTER(A69,"["),"]") -> WEB | C69: Sanity | D69: Release 2 | E69: Passed
A70: CARDS- TRANSACTIONS - DETAILS_[Android] | B70: =_xlfn.TEXTBEFORE(_xlfn.TEXTAFTER(A70,"["),"]") -> Android | C70: Sanity | D70: Release 2 | E70: Passed
A71: CURRENT DOMESTIC ACCOUNTS - DETAILS_[Android] | B71: =_xlfn.TEXTBEFORE(_xlfn.TEXTAFTER(A71,"["),"]") -> Android | C71: Critical | D71: Release 1 | E71: Failed - New bug
A72: CURRENT DOMESTIC ACCOUNTS - DETAILS_[iOS] | B72: =_xlfn.TEXTBEFORE(_xlfn.TEXTAFTER(A72,"["),"]") -> iOS | C72: Critical | D72: Release 1 | E72: Passed
A73: SAVINGS ACCOUNTS - TRANSACTIONS - LIST_[WEB] | B73: =_xlfn.TEXTBEFORE(_xlfn.TEXTAFTER(A73,"["),"]") -> WEB | C73: Critical | D73: Release 1 | E73: Conditionally Passed
...
